Workbook

Sheet README
C2: Análisis financiero de causa raíz sobre la erosión de márgenes en un negocio de repostería artesanal
D5: Meta SMART:
C6: Este negocio no ha tenido actividad desde octubre de 2025 debido a una reubicación geográfica. El objetivo es que durante el primer
C7: trimestre de reactivación operativa, se alcance un Margen Bruto mínimo del 65%, esto, a través de una reingeniería de las recetas
C8: y una actualización dinámica de los precios.
N31: * El MGB se redujo un 5.86% respecto al año anterior.
D35: Para entender dicha erosión (que en volumen de ventas se tradujo al 8.41%), este análisis pretende responder las siguiente preguntas:
D58: Los análisis cuantitativos llevados a cabo en este proyecto, permiten traducir estas variables numéricas en un panorama estratégico. En seguida se
D59: muestra la matriz FODA, la cual sintetiza los hallazgos en la base de datos los cuales serán la base para el plan de acción y el relanzamiento
D60: comercial.
D86: Metodología (ETL)
D88: Unificación de medidas. Se homogenizaron las métricas | I88: Unión de datos. Se vincularon listas de precios antiguos
D89: para asegurar una comparación objetiva en ambos años. | I89: y nuevos para crear una visión completa del historial del
I90: negocio.
D91: Auditoría de datos. Se detectaron valores nulos y se
D92: completaron con la información correspondiente, | I92: Modelado. Se creó una tabla maestra la cual es un motor | R92: 🔡
D93: asegurando que los cálculos sean precisos. | I93: de escenarios dinámicos para el análisis de sensibilidad.
D96: Glosario
D98: CV | E98: Costo de Ventas | G98: SMV | H98: Sales Mix Variance
D99: ETL | E99: Extract, Transform, Load | G99: TotalCV | H99: Total Costo de Ventas
D100: GO | E100: Gastos Opercionales | G100: UB | H100: Utilidad Bruta
D101: ID | E101: Identificación de productos | G101: UN | H101: Utilidad Neta
D102: IT | E102: Ingresos Totales | G102: UO | H102: Utilidad Operativa
D103: MGB | E103: Margen de Ganancia Bruta | G103: VariaciónMoM | H103: Variación Month over Month
D104: MixVtas$ | E104: Mix Ventas Ingresos Totales | G104: VariaciónWoW | H104: Variación Week over Week
D105: MixVtasQ | E105: Mix Ventas Quantity | G105: VariaciónYoY | H105: Variación Year over Year
D106: MU | E106: Margen Unitario

Sheet Insights&Resultados
B2: ¿Qué productos mantuvieron la RENTABILIDAD del negocio?
B19: El 62.5% de los productos ofertados generan poco más del 80% de Utilidad Bruta.
B20: Negocio estable por la alta rentabilidad de los productos estrella, utilidades diversificadas, esto reduce el riesgo operativo pero se pueden optimizar los productos que
B21: aportan menos valor. Requiere atender ciertas áreas para que así siga en el futuro, estas son:
B22: - La merma de los productos más vendidos, ya que esto afecta mucho el MGB.
B23: - Implementar estrategias con los productos menos vendidos y con un MGB bajo.
B24: - Establecer acciones para lograr subir el PV, ya que el CV subió más del triple en su mayoría.
B28: ¿El nulo aumento de casi todos los PRECIOS DE VENTA fue la única causa de la disminución del MARGEN DE GANANCIA BRUTO?
B31: Escenario B (PV 2025 VS CV 2024) | F31: ="Margen Bruto General "& B31 -> Margen Bruto General Escenario B (PV 2025 VS CV 2024)
B34: PV (promedio) | C34: =IF($B$31="2025 (Real)",(AVERAGE('Maestro de productos 2025'!$D$189:$D$196)),IF($B$31="Escenario A (PV 2025+10% VS CV 2025)",(AVERAGE('Maestro de productos 2025'!$D$189:$D$196)*1.1),(AVERAGE('Maestro de productos 2025'!$D$189:$D$196)))) -> 17.625
G35: Real 2025 | H35: =README!$G$14 -> 0.59264977
B36: CV (promedio) | C36: =IF($B$31="2025 (Real)",AVERAGE('Maestro de productos 2025'!$E$189:$E$196),IF($B$31="Escenario A (PV 2025+10% VS CV 2025)",AVERAGE('Maestro de productos 2025'!$E$189:$E$196),AVERAGE('Maestro de productos 2024'!$E$189:$E$196))) -> 6.1195789 | G36: =$B$31 -> Escenario B (PV 2025 VS CV 2024) | H36: =$C$38 -> 0.65631956
B38: MGB | C38: =IF($B$31="2025 (Real)",README!G14,IF($B$31="Escenario A (PV 2025+10% VS CV 2025)",(('Dashboard de rentabilidad'!$C$33-'Dashboard de rentabilidad'!$D$31)/'Dashboard de rentabilidad'!$C$33),('Dashboard de rentabilidad'!$P$58-'Dashboard de rentabilidad'!$Q$58)/'Dashboard de rentabilidad'!$P$58)) -> 0.65631956
B40: Conclusión | C40: =IF($B$31="2025 (Real)","Margen bajo",IF($B$31="Escenario A (PV 2025+10% VS CV 2025)","Margen recuperado con solo aumentar 10% el PV","La inflación fue la causa raíz de la baja del MGB")) -> La inflación fue la causa raíz de la baja del MGB
B43: El análisis de sensibilidad actúa como validación matemática de la Causa Raíz
B44: En el Escenario B (PV 2025 VS CV 2024, se puede comprobar que la estructura
B45: operativa era sana, pero el entorno macroeconómico externo y aunado a la
B46: falta de acoplar los precios de venta fueron los detonantes de la caída del
B47: MGB.
B51: Teniendo en cuenta que el 62.5% de los productos conforman más del 80% de la Utilidad Bruta (ver gráficos de arriba), se tendrá que hacer una reestructuración
B52: de dichos productos para aumentar el PV, bajar mermas, así como también se deberá buscar distintos proveedores con el fin de mejorar costos y subir el MGB.
B53: Aunado a esto, hubo una disminución del 8.41% en el volumen de ventas y aunque tuvo un impacto en la caída del MGB, no fue tan grande la repercusión como sí
B54: lo fue la inflación.
B58: ¿Qué recetas necesitan REESTRUTURACIÓN?
B61: Producto | C61: MGB | D61: Estatus | E61: Acciones
B62: ID-3824 | C62: ='Maestro de productos 2025'!M189/'Maestro de productos 2025'!J189 -> 0.5928256 | D62: =IFS( OR(C62 < 0.45,'Maestro de productos 2025'!G189 < 'Maestro de productos 2025'!$G$198), "🟧 Crítico (Revisar Costos o Rotación)", AND(C62 >= 0.6,'Maestro de productos 2025'!G189 >= 'Maestro de productos 2025'!$G$198), "🟪 Excelente (Alta Rentabilidad y Ventas)", TRUE, "🟨 Estable / Alerta (Monitorear Estrategia)" ) -> 🟨 Estable / Alerta (Monitorear Estrategia) | E62: Abastecimiento estratégico, evitar que no haya inventario ni bajar la calidad
B63: ID-3825 | C63: ='Maestro de productos 2025'!M190/'Maestro de productos 2025'!J190 -> 0.58941974 | D63: =IFS( OR(C63 < 0.45,'Maestro de productos 2025'!G190 < 'Maestro de productos 2025'!$G$198), "🟧 Crítico (Revisar Costos o Rotación)", AND(C63 >= 0.6,'Maestro de productos 2025'!G190 >= 'Maestro de productos 2025'!$G$198), "🟪 Excelente (Alta Rentabilidad y Ventas)", TRUE, "🟨 Estable / Alerta (Monitorear Estrategia)" ) -> 🟨 Estable / Alerta (Monitorear Estrategia) | E63: Reingeniería del producto para reducir la merma operativa. Aumentar ventas.
B64: ID-3826 | C64: ='Maestro de productos 2025'!M191/'Maestro de productos 2025'!J191 -> 0.59634383 | D64: =IFS( OR(C64 < 0.45,'Maestro de productos 2025'!G191 < 'Maestro de productos 2025'!$G$198), "🟧 Crítico (Revisar Costos o Rotación)", AND(C64 >= 0.6,'Maestro de productos 2025'!G191 >= 'Maestro de productos 2025'!$G$198), "🟪 Excelente (Alta Rentabilidad y Ventas)", TRUE, "🟨 Estable / Alerta (Monitorear Estrategia)" ) -> 🟨 Estable / Alerta (Monitorear Estrategia) | E64: Abastecimiento estratégico. Aumentar ventas.
B65: ID-3827 | C65: ='Maestro de productos 2025'!M192/'Maestro de productos 2025'!J192 -> 0.55546007 | D65: =IFS( OR(C65 < 0.45,'Maestro de productos 2025'!G192 < 'Maestro de productos 2025'!$G$198), "🟧 Crítico (Revisar Costos o Rotación)", AND(C65 >= 0.6,'Maestro de productos 2025'!G192 >= 'Maestro de productos 2025'!$G$198), "🟪 Excelente (Alta Rentabilidad y Ventas)", TRUE, "🟨 Estable / Alerta (Monitorear Estrategia)" ) -> 🟨 Estable / Alerta (Monitorear Estrategia) | E65: Abastecimiento estratégico. Aumentar ventas y mejorar proceso de producción.
B66: ID-3828 | C66: ='Maestro de productos 2025'!M193/'Maestro de productos 2025'!J193 -> 0.60193566 | D66: =IFS( OR(C66 < 0.45,'Maestro de productos 2025'!G193 < 'Maestro de productos 2025'!$G$198), "🟧 Crítico (Revisar Costos o Rotación)", AND(C66 >= 0.6,'Maestro de productos 2025'!G193 >= 'Maestro de productos 2025'!$G$198), "🟪 Excelente (Alta Rentabilidad y Ventas)", TRUE, "🟨 Estable / Alerta (Monitorear Estrategia)" ) -> 🟪 Excelente (Alta Rentabilidad y Ventas) | E66: Abastecimiento estratégico
B67: ID-3829 | C67: ='Maestro de productos 2025'!M194/'Maestro de productos 2025'!J194 -> 0.59879238 | D67: =IFS( OR(C67 < 0.45,'Maestro de productos 2025'!G194 < 'Maestro de productos 2025'!$G$198), "🟧 Crítico (Revisar Costos o Rotación)", AND(C67 >= 0.6,'Maestro de productos 2025'!G194 >= 'Maestro de productos 2025'!$G$198), "🟪 Excelente (Alta Rentabilidad y Ventas)", TRUE, "🟨 Estable / Alerta (Monitorear Estrategia)" ) -> 🟧 Crítico (Revisar Costos o Rotación) | E67: Urge incrementar volumen de ventas / ingeniería de valor.
B68: ID-3830 | C68: ='Maestro de productos 2025'!M195/'Maestro de productos 2025'!J195 -> 0.58838362 | D68: =IFS( OR(C68 < 0.45,'Maestro de productos 2025'!G195 < 'Maestro de productos 2025'!$G$198), "🟧 Crítico (Revisar Costos o Rotación)", AND(C68 >= 0.6,'Maestro de productos 2025'!G195 >= 'Maestro de productos 2025'!$G$198), "🟪 Excelente (Alta Rentabilidad y Ventas)", TRUE, "🟨 Estable / Alerta (Monitorear Estrategia)" ) -> 🟧 Crítico (Revisar Costos o Rotación) | E68: Urge incrementar volumen de ventas / ingeniería de valor.
B69: ID-3831 | C69: ='Maestro de productos 2025'!M196/'Maestro de productos 2025'!J196 -> 0.605512 | D69: =IFS( OR(C69 < 0.45,'Maestro de productos 2025'!G196 < 'Maestro de productos 2025'!$G$198), "🟧 Crítico (Revisar Costos o Rotación)", AND(C69 >= 0.6,'Maestro de productos 2025'!G196 >= 'Maestro de productos 2025'!$G$198), "🟪 Excelente (Alta Rentabilidad y Ventas)", TRUE, "🟨 Estable / Alerta (Monitorear Estrategia)" ) -> 🟪 Excelente (Alta Rentabilidad y Ventas) | E69: Abastecimiento estratégico. Aumentar ventas.
B71: El producto ID-3827 necesita atención urgente, ya que al pertenecer al 62.5% anteriomente descrito, es de los productos que contribuyen más al MGB, y se consideran
B72: parte esencial de la rentabilidad del negocio pero los costos y tiempos de producción necesitan atención urgente. Tomando estos puntos a consideración, se llegó a la
B73: conclusión que un abastecimiento estratégico bastará para llegar a la meta en los 3 meses programados.
B75: Los dos productos con el peor rendimiento, ID3829 e ID-3830, mantuvieron un margen unitario más saludable pero no fue suficiente, sus ventas bajaron drásticamente,
B76: ya que la relación costo-producto no convencieron a los clientes.
B80: CONCLUSIÓN
B82: Se concluye que la erosión del 3.69% anual del Margen de Ganancia Bruta, se debió a la inflación acelerada sobre los insumos y el bajo aumento y desigualdad de los
...

Sheet Análisis Descriptivo
A1: ID | B1: Producto | C1: PV | D1: CV | E1: MU | F1: TotalCV | G1: IT | H1: UB | I1: IT(semanal) | J1: VariacionWoW(I) | K1: MGB(semanal) | L1: UB(semanal) | M1: VariacionWoW(UB) | N1: IT(mensual) | O1: VariacionMoM(I) | P1: MGB(mensual) | Q1: UB(mensual) | R1: VariacionMoM(UB) | S1: IT(anual) | T1: VariacionYoY(I) | U1: MGB(anual) | V1: UB(anual) | W1: VariacionYoY(UB)
A2: {=XLOOKUP($B2,'Maestro de productos 2024'!$A$3:$A$163,'Maestro de productos 2024'!$B$3:$B$163,0)} -> ID-3824 | B2: Galletas chocochips | C2: {=XLOOKUP(B2,'Maestro de productos 2024'!$B$189:$B$196,'Maestro de productos 2024'!$D$189:$D$196,"No encontrado",0)} -> 10 | D2: {=XLOOKUP(B2,'Maestro de productos 2024'!$B$189:$B$196,'Maestro de productos 2024'!$E$189:$E$196,"No encontrado",0)} -> 3.3375513 | E2: =C2-D2 -> 6.6624487 | F2: =('Base de datos transacciones'!$H2)*$D2 -> 106.80164 | G2: ='Base de datos transacciones'!$H2*$C2 -> 320 | H2: =G2-F2 -> 213.19836 | I2: =SUM(G2) -> 320 | K2: =(I2-(SUM(F2)))/I2 -> 0.66624487 | L2: =I2-(SUM(F2)) -> 213.19836
A3: {=XLOOKUP($B3,'Maestro de productos 2024'!$A$3:$A$163,'Maestro de productos 2024'!$B$3:$B$163,0)} -> ID-3824 | B3: Galletas chocochips | C3: {=XLOOKUP(B3,'Maestro de productos 2024'!$B$189:$B$196,'Maestro de productos 2024'!$D$189:$D$196,"No encontrado",0)} -> 10 | D3: {=XLOOKUP(B3,'Maestro de productos 2024'!$B$189:$B$196,'Maestro de productos 2024'!$E$189:$E$196,"No encontrado",0)} -> 3.3375513 | E3: =C3-D3 -> 6.6624487 | F3: =('Base de datos transacciones'!$H3)*$D3 -> 213.60328 | G3: ='Base de datos transacciones'!$H3*$C3 -> 640 | H3: =G3-F3 -> 426.39672 | I3: =SUM(G3) -> 640 | J3: =((I3-I2)/I2) -> 1 | K3: =(I3-(SUM(F3)))/I3 -> 0.66624487 | L3: =I3-(SUM(F3)) -> 426.39672 | M3: =((L3-L2)/L2) -> 1 | N3: =SUM(G2:G3) -> 960 | P3: =(N3-SUM(F2:F3))/N3 -> 0.66624487 | Q3: =N3-(SUM(F2:F3)) -> 639.59508
A4: {=XLOOKUP($B4,'Maestro de productos 2024'!$A$3:$A$163,'Maestro de productos 2024'!$B$3:$B$163,0)} -> ID-3826 | B4: Brownie triple chocolate | C4: {=XLOOKUP(B4,'Maestro de productos 2024'!$B$189:$B$196,'Maestro de productos 2024'!$D$189:$D$196,"No encontrado",0)} -> 20 | D4: {=XLOOKUP(B4,'Maestro de productos 2024'!$B$189:$B$196,'Maestro de productos 2024'!$E$189:$E$196,"No encontrado",0)} -> 7.1039722 | E4: =C4-D4 -> 12.896028 | F4: =('Base de datos transacciones'!$H4)*$D4 -> 127.8715 | G4: ='Base de datos transacciones'!$H4*$C4 -> 360 | H4: =G4-F4 -> 232.1285 | I4: =SUM(G4) -> 360 | J4: =((I4-I3)/I3) -> -0.4375 | K4: =(I4-(SUM(F4)))/I4 -> 0.64480139 | L4: =I4-(SUM(F4)) -> 232.1285 | M4: =((L4-L3)/L3) -> -0.45560439
A5: {=XLOOKUP($B5,'Maestro de productos 2024'!$A$3:$A$163,'Maestro de productos 2024'!$B$3:$B$163,0)} -> ID-3827 | B5: Galletas danesas | C5: {=XLOOKUP(B5,'Maestro de productos 2024'!$B$189:$B$196,'Maestro de productos 2024'!$D$189:$D$196,"No encontrado",0)} -> 7 | D5: {=XLOOKUP(B5,'Maestro de productos 2024'!$B$189:$B$196,'Maestro de productos 2024'!$E$189:$E$196,"No encontrado",0)} -> 2.6234601 | E5: =C5-D5 -> 4.3765399 | F5: =('Base de datos transacciones'!$H5)*$D5 -> 91.821103 | G5: ='Base de datos transacciones'!$H5*$C5 -> 245 | H5: =G5-F5 -> 153.1789 | I5: =SUM(G5) -> 245 | J5: =((I5-I4)/I4) -> -0.31944444 | K5: =(I5-(SUM(F5)))/I5 -> 0.62521999 | L5: =I5-(SUM(F5)) -> 153.1789 | M5: =((L5-L4)/L4) -> -0.34011163
A6: {=XLOOKUP($B6,'Maestro de productos 2024'!$A$3:$A$163,'Maestro de productos 2024'!$B$3:$B$163,0)} -> ID-3824 | B6: Galletas chocochips | C6: {=XLOOKUP(B6,'Maestro de productos 2024'!$B$189:$B$196,'Maestro de productos 2024'!$D$189:$D$196,"No encontrado",0)} -> 10 | D6: {=XLOOKUP(B6,'Maestro de productos 2024'!$B$189:$B$196,'Maestro de productos 2024'!$E$189:$E$196,"No encontrado",0)} -> 3.3375513 | E6: =C6-D6 -> 6.6624487 | F6: =('Base de datos transacciones'!$H6)*$D6 -> 213.60328 | G6: ='Base de datos transacciones'!$H6*$C6 -> 640 | H6: =G6-F6 -> 426.39672
A7: {=XLOOKUP($B7,'Maestro de productos 2024'!$A$3:$A$163,'Maestro de productos 2024'!$B$3:$B$163,0)} -> ID-3825 | B7: Mini cheesecake | C7: {=XLOOKUP(B7,'Maestro de productos 2024'!$B$189:$B$196,'Maestro de productos 2024'!$D$189:$D$196,"No encontrado",0)} -> 20 | D7: {=XLOOKUP(B7,'Maestro de productos 2024'!$B$189:$B$196,'Maestro de productos 2024'!$E$189:$E$196,"No encontrado",0)} -> 7.6091462 | E7: =C7-D7 -> 12.390854 | F7: =('Base de datos transacciones'!$H7)*$D7 -> 121.74634 | G7: ='Base de datos transacciones'!$H7*$C7 -> 320 | H7: =G7-F7 -> 198.25366 | I7: =SUM(G6:G7) -> 960 | J7: =((I7-I5)/I5) -> 2.9183673 | K7: =(I7-(SUM(F6:F7)))/I7 -> 0.65067748 | L7: =I7-(SUM(F6:F7)) -> 624.65038 | M7: =((L7-L5)/L5) -> 3.077914
A8: {=XLOOKUP($B8,'Maestro de productos 2024'!$A$3:$A$163,'Maestro de productos 2024'!$B$3:$B$163,0)} -> ID-3826 | B8: Brownie triple chocolate | C8: {=XLOOKUP(B8,'Maestro de productos 2024'!$B$189:$B$196,'Maestro de productos 2024'!$D$189:$D$196,"No encontrado",0)} -> 20 | D8: {=XLOOKUP(B8,'Maestro de productos 2024'!$B$189:$B$196,'Maestro de productos 2024'!$E$189:$E$196,"No encontrado",0)} -> 7.1039722 | E8: =C8-D8 -> 12.896028 | F8: =('Base de datos transacciones'!$H8)*$D8 -> 255.743 | G8: ='Base de datos transacciones'!$H8*$C8 -> 720 | H8: =G8-F8 -> 464.257
A9: {=XLOOKUP($B9,'Maestro de productos 2024'!$A$3:$A$163,'Maestro de productos 2024'!$B$3:$B$163,0)} -> ID-3827 | B9: Galletas danesas | C9: {=XLOOKUP(B9,'Maestro de productos 2024'!$B$189:$B$196,'Maestro de productos 2024'!$D$189:$D$196,"No encontrado",0)} -> 7 | D9: {=XLOOKUP(B9,'Maestro de productos 2024'!$B$189:$B$196,'Maestro de productos 2024'!$E$189:$E$196,"No encontrado",0)} -> 2.6234601 | E9: =C9-D9 -> 4.3765399 | F9: =('Base de datos transacciones'!$H9)*$D9 -> 91.821103 | G9: ='Base de datos transacciones'!$H9*$C9 -> 245 | H9: =G9-F9 -> 153.1789 | I9: =SUM(G8:G9) -> 965 | J9: =((I9-I7)/I7) -> 0.0052083333 | K9: =(I9-(SUM(F8:F9)))/I9 -> 0.63982995 | L9: =I9-(SUM(F8:F9)) -> 617.4359 | M9: =((L9-L7)/L7) -> -0.01154963 | N9: =SUM(G4:G9) -> 2530 | O9: =((N9-N3)/N3) -> 1.6354167 | P9: =(N9-SUM(F4:F9))/N9 -> 0.64323861 | Q9: =N9-(SUM(F4:F9)) -> 1627.3937 | R9: =((Q9-Q3)/Q3) -> 1.5444124
A10: {=XLOOKUP($B10,'Maestro de productos 2024'!$A$3:$A$163,'Maestro de productos 2024'!$B$3:$B$163,0)} -> ID-3828 | B10: Muffins de yogurt | C10: {=XLOOKUP(B10,'Maestro de productos 2024'!$B$189:$B$196,'Maestro de productos 2024'!$D$189:$D$196,"No encontrado",0)} -> 20 | D10: {=XLOOKUP(B10,'Maestro de productos 2024'!$B$189:$B$196,'Maestro de productos 2024'!$E$189:$E$196,"No encontrado",0)} -> 7.3010641 | E10: =C10-D10 -> 12.698936 | F10: =('Base de datos transacciones'!$H10)*$D10 -> 175.22554 | G10: ='Base de datos transacciones'!$H10*$C10 -> 480 | H10: =G10-F10 -> 304.77446
A11: {=XLOOKUP($B11,'Maestro de productos 2024'!$A$3:$A$163,'Maestro de productos 2024'!$B$3:$B$163,0)} -> ID-3824 | B11: Galletas chocochips | C11: {=XLOOKUP(B11,'Maestro de productos 2024'!$B$189:$B$196,'Maestro de productos 2024'!$D$189:$D$196,"No encontrado",0)} -> 10 | D11: {=XLOOKUP(B11,'Maestro de productos 2024'!$B$189:$B$196,'Maestro de productos 2024'!$E$189:$E$196,"No encontrado",0)} -> 3.3375513 | E11: =C11-D11 -> 6.6624487 | F11: =('Base de datos transacciones'!$H11)*$D11 -> 100.12654 | G11: ='Base de datos transacciones'!$H11*$C11 -> 300 | H11: =G11-F11 -> 199.87346 | I11: =SUM(G10:G11) -> 780 | J11: =((I11-I9)/I9) -> -0.19170984 | K11: =(I11-(SUM(F10:F11)))/I11 -> 0.64698452 | L11: =I11-(SUM(F10:F11)) -> 504.64792 | M11: =((L11-L9)/L9) -> -0.18267155
A12: {=XLOOKUP($B12,'Maestro de productos 2024'!$A$3:$A$163,'Maestro de productos 2024'!$B$3:$B$163,0)} -> ID-3825 | B12: Mini cheesecake | C12: {=XLOOKUP(B12,'Maestro de productos 2024'!$B$189:$B$196,'Maestro de productos 2024'!$D$189:$D$196,"No encontrado",0)} -> 20 | D12: {=XLOOKUP(B12,'Maestro de productos 2024'!$B$189:$B$196,'Maestro de productos 2024'!$E$189:$E$196,"No encontrado",0)} -> 7.6091462 | E12: =C12-D12 -> 12.390854 | F12: =('Base de datos transacciones'!$H12)*$D12 -> 121.74634 | G12: ='Base de datos transacciones'!$H12*$C12 -> 320 | H12: =G12-F12 -> 198.25366
A13: {=XLOOKUP($B13,'Maestro de productos 2024'!$A$3:$A$163,'Maestro de productos 2024'!$B$3:$B$163,0)} -> ID-3824 | B13: Galletas chocochips | C13: {=XLOOKUP(B13,'Maestro de productos 2024'!$B$189:$B$196,'Maestro de productos 2024'!$D$189:$D$196,"No encontrado",0)} -> 10 | D13: {=XLOOKUP(B13,'Maestro de productos 2024'!$B$189:$B$196,'Maestro de productos 2024'!$E$189:$E$196,"No encontrado",0)} -> 3.3375513 | E13: =C13-D13 -> 6.6624487 | F13: =('Base de datos transacciones'!$H13)*$D13 -> 106.80164 | G13: ='Base de datos transacciones'!$H13*$C13 -> 320 | H13: =G13-F13 -> 213.19836 | I13: =SUM(G12:G13) -> 640 | J13: =((I13-I11)/I11) -> -0.17948718 | K13: =(I13-(SUM(F12:F13)))/I13 -> 0.64289378 | L13: =I13-(SUM(F12:F13)) -> 411.45202 | M13: =((L13-L11)/L11) -> -0.1846751
A14: {=XLOOKUP($B14,'Maestro de productos 2024'!$A$3:$A$163,'Maestro de productos 2024'!$B$3:$B$163,0)} -> ID-3826 | B14: Brownie triple chocolate | C14: {=XLOOKUP(B14,'Maestro de productos 2024'!$B$189:$B$196,'Maestro de productos 2024'!$D$189:$D$196,"No encontrado",0)} -> 20 | D14: {=XLOOKUP(B14,'Maestro de productos 2024'!$B$189:$B$196,'Maestro de productos 2024'!$E$189:$E$196,"No encontrado",0)} -> 7.1039722 | E14: =C14-D14 -> 12.896028 | F14: =('Base de datos transacciones'!$H14)*$D14 -> 127.8715 | G14: ='Base de datos transacciones'!$H14*$C14 -> 360 | H14: =G14-F14 -> 232.1285
A15: {=XLOOKUP($B15,'Maestro de productos 2024'!$A$3:$A$163,'Maestro de productos 2024'!$B$3:$B$163,0)} -> ID-3828 | B15: Muffins de yogurt | C15: {=XLOOKUP(B15,'Maestro de productos 2024'!$B$189:$B$196,'Maestro de productos 2024'!$D$189:$D$196,"No encontrado",0)} -> 20 | D15: {=XLOOKUP(B15,'Maestro de productos 2024'!$B$189:$B$196,'Maestro de productos 2024'!$E$189:$E$196,"No encontrado",0)} -> 7.3010641 | E15: =C15-D15 -> 12.698936 | F15: =('Base de datos transacciones'!$H15)*$D15 -> 175.22554 | G15: ='Base de datos transacciones'!$H15*$C15 -> 480 | H15: =G15-F15 -> 304.77446 | I15: =SUM(G14:G15) -> 840 | J15: =((I15-I13)/I13) -> 0.3125 | K15: =(I15-(SUM(F14:F15)))/I15 -> 0.63917019 | L15: =I15-(SUM(F14:F15)) -> 536.90296 | M15: =((L15-L13)/L13) -> 0.30489811
A16: {=XLOOKUP($B16,'Maestro de productos 2024'!$A$3:$A$163,'Maestro de productos 2024'!$B$3:$B$163,0)} -> ID-3828 | B16: Muffins de yogurt | C16: {=XLOOKUP(B16,'Maestro de productos 2024'!$B$189:$B$196,'Maestro de productos 2024'!$D$189:$D$196,"No encontrado",0)} -> 20 | D16: {=XLOOKUP(B16,'Maestro de productos 2024'!$B$189:$B$196,'Maestro de productos 2024'!$E$189:$E$196,"No encontrado",0)} -> 7.3010641 | E16: =C16-D16 -> 12.698936 | F16: =('Base de datos transacciones'!$H16)*$D16 -> 87.612769 | G16: ='Base de datos transacciones'!$H16*$C16 -> 240 | H16: =G16-F16 -> 152.38723
A17: {=XLOOKUP($B17,'Maestro de productos 2024'!$A$3:$A$163,'Maestro de productos 2024'!$B$3:$B$163,0)} -> ID-3824 | B17: Galletas chocochips | C17: {=XLOOKUP(B17,'Maestro de productos 2024'!$B$189:$B$196,'Maestro de productos 2024'!$D$189:$D$196,"No encontrado",0)} -> 10 | D17: {=XLOOKUP(B17,'Maestro de productos 2024'!$B$189:$B$196,'Maestro de productos 2024'!$E$189:$E$196,"No encontrado",0)} -> 3.3375513 | E17: =C17-D17 -> 6.6624487 | F17: =('Base de datos transacciones'!$H17)*$D17 -> 96.788987 | G17: ='Base de datos transacciones'!$H17*$C17 -> 290 | H17: =G17-F17 -> 193.21101 | I17: =SUM(G16:G17) -> 530 | J17: =((I17-I15)/I15) -> -0.36904762 | K17: =(I17-(SUM(F16:F17)))/I17 -> 0.65207216 | L17: =I17-(SUM(F16:F17)) -> 345.59824 | M17: =((L17-L15)/L15) -> -0.35631153
A18: {=XLOOKUP($B18,'Maestro de productos 2024'!$A$3:$A$163,'Maestro de productos 2024'!$B$3:$B$163,0)} -> ID-3825 | B18: Mini cheesecake | C18: {=XLOOKUP(B18,'Maestro de productos 2024'!$B$189:$B$196,'Maestro de productos 2024'!$D$189:$D$196,"No encontrado",0)} -> 20 | D18: {=XLOOKUP(B18,'Maestro de productos 2024'!$B$189:$B$196,'Maestro de productos 2024'!$E$189:$E$196,"No encontrado",0)} -> 7.6091462 | E18: =C18-D18 -> 12.390854 | F18: =('Base de datos transacciones'!$H18)*$D18 -> 106.52805 | G18: ='Base de datos transacciones'!$H18*$C18 -> 280 | H18: =G18-F18 -> 173.47195
A19: {=XLOOKUP($B19,'Maestro de productos 2024'!$A$3:$A$163,'Maestro de productos 2024'!$B$3:$B$163,0)} -> ID-3827 | B19: Galletas danesas | C19: {=XLOOKUP(B19,'Maestro de productos 2024'!$B$189:$B$196,'Maestro de productos 2024'!$D$189:$D$196,"No encontrado",0)} -> 7 | D19: {=XLOOKUP(B19,'Maestro de productos 2024'!$B$189:$B$196,'Maestro de productos 2024'!$E$189:$E$196,"No encontrado",0)} -> 2.6234601 | E19: =C19-D19 -> 4.3765399 | F19: =('Base de datos transacciones'!$H19)*$D19 -> 91.821103 | G19: ='Base de datos transacciones'!$H19*$C19 -> 245 | H19: =G19-F19 -> 153.1789 | I19: =SUM(G18:G19) -> 525 | J19: =((I19-I17)/I17) -> -0.0094339623 | K19: =(I19-(SUM(F18:F19)))/I19 -> 0.6221921 | L19: =I19-(SUM(F18:F19)) -> 326.65085 | M19: =((L19-L17)/L17) -> -0.054824913 | N19: =SUM(G10:G19) -> 3315 | O19: =((N19-N9)/N9) -> 0.31027668 | P19: =(N19-SUM(F10:F19))/N19 -> 0.64110166 | Q19: =N19-(SUM(F10:F19)) -> 2125.252 | R19: =((Q19-Q9)/Q9) -> 0.30592372
A20: {=XLOOKUP($B20,'Maestro de productos 2024'!$A$3:$A$163,'Maestro de productos 2024'!$B$3:$B$163,0)} -> ID-3827 | B20: Galletas danesas | C20: {=XLOOKUP(B20,'Maestro de productos 2024'!$B$189:$B$196,'Maestro de productos 2024'!$D$189:$D$196,"No encontrado",0)} -> 7 | D20: {=XLOOKUP(B20,'Maestro de productos 2024'!$B$189:$B$196,'Maestro de productos 2024'!$E$189:$E$196,"No encontrado",0)} -> 2.6234601 | E20: =C20-D20 -> 4.3765399 | F20: =('Base de datos transacciones'!$H20)*$D20 -> 89.197642 | G20: ='Base de datos transacciones'!$H20*$C20 -> 238 | H20: =G20-F20 -> 148.80236
A21: {=XLOOKUP($B21,'Maestro de productos 2024'!$A$3:$A$163,'Maestro de productos 2024'!$B$3:$B$163,0)} -> ID-3826 | B21: Brownie triple chocolate | C21: {=XLOOKUP(B21,'Maestro de productos 2024'!$B$189:$B$196,'Maestro de productos 2024'!$D$189:$D$196,"No encontrado",0)} -> 20 | D21: {=XLOOKUP(B21,'Maestro de productos 2024'!$B$189:$B$196,'Maestro de productos 2024'!$E$189:$E$196,"No encontrado",0)} -> 7.1039722 | E21: =C21-D21 -> 12.896028 | F21: =('Base de datos transacciones'!$H21)*$D21 -> 127.8715 | G21: ='Base de datos transacciones'!$H21*$C21 -> 360 | H21: =G21-F21 -> 232.1285 | I21: =SUM(G20:G21) -> 598 | J21: =((I21-I19)/I19) -> 0.13904762 | K21: =(I21-(SUM(F20:F21)))/I21 -> 0.63700812 | L21: =I21-(SUM(F20:F21)) -> 380.93086 | M21: =((L21-L19)/L19) -> 0.16617133
A22: {=XLOOKUP($B22,'Maestro de productos 2024'!$A$3:$A$163,'Maestro de productos 2024'!$B$3:$B$163,0)} -> ID-3828 | B22: Muffins de yogurt | C22: {=XLOOKUP(B22,'Maestro de productos 2024'!$B$189:$B$196,'Maestro de productos 2024'!$D$189:$D$196,"No encontrado",0)} -> 20 | D22: {=XLOOKUP(B22,'Maestro de productos 2024'!$B$189:$B$196,'Maestro de productos 2024'!$E$189:$E$196,"No encontrado",0)} -> 7.3010641 | E22: =C22-D22 -> 12.698936 | F22: =('Base de datos transacciones'!$H22)*$D22 -> 175.22554 | G22: ='Base de datos transacciones'!$H22*$C22 -> 480 | H22: =G22-F22 -> 304.77446
A23: {=XLOOKUP($B23,'Maestro de productos 2024'!$A$3:$A$163,'Maestro de productos 2024'!$B$3:$B$163,0)} -> ID-3824 | B23: Galletas chocochips | C23: {=XLOOKUP(B23,'Maestro de productos 2024'!$B$189:$B$196,'Maestro de productos 2024'!$D$189:$D$196,"No encontrado",0)} -> 10 | D23: {=XLOOKUP(B23,'Maestro de productos 2024'!$B$189:$B$196,'Maestro de productos 2024'!$E$189:$E$196,"No encontrado",0)} -> 3.3375513 | E23: =C23-D23 -> 6.6624487 | F23: =('Base de datos transacciones'!$H23)*$D23 -> 106.80164 | G23: ='Base de datos transacciones'!$H23*$C23 -> 320 | H23: =G23-F23 -> 213.19836 | I23: =SUM(G22:G23) -> 800 | J23: =((I23-I21)/I21) -> 0.33779264 | K23: =(I23-(SUM(F22:F23)))/I23 -> 0.64746603 | L23: =I23-(SUM(F22:F23)) -> 517.97282 | M23: =((L23-L21)/L21) -> 0.35975548
A24: {=XLOOKUP($B24,'Maestro de productos 2024'!$A$3:$A$163,'Maestro de productos 2024'!$B$3:$B$163,0)} -> ID-3826 | B24: Brownie triple chocolate | C24: {=XLOOKUP(B24,'Maestro de productos 2024'!$B$189:$B$196,'Maestro de productos 2024'!$D$189:$D$196,"No encontrado",0)} -> 20 | D24: {=XLOOKUP(B24,'Maestro de productos 2024'!$B$189:$B$196,'Maestro de productos 2024'!$E$189:$E$196,"No encontrado",0)} -> 7.1039722 | E24: =C24-D24 -> 12.896028 | F24: =('Base de datos transacciones'!$H24)*$D24 -> 255.743 | G24: ='Base de datos transacciones'!$H24*$C24 -> 720 | H24: =G24-F24 -> 464.257
A25: {=XLOOKUP($B25,'Maestro de productos 2024'!$A$3:$A$163,'Maestro de productos 2024'!$B$3:$B$163,0)} -> ID-3829 | B25: Besos de nuez | C25: {=XLOOKUP(B25,'Maestro de productos 2024'!$B$189:$B$196,'Maestro de productos 2024'!$D$189:$D$196,"No encontrado",0)} -> 7 | D25: {=XLOOKUP(B25,'Maestro de productos 2024'!$B$189:$B$196,'Maestro de productos 2024'!$E$189:$E$196,"No encontrado",0)} -> 2.9898436 | E25: =C25-D25 -> 4.0101564 | F25: =('Base de datos transacciones'!$H25)*$D25 -> 149.49218 | G25: ='Base de datos transacciones'!$H25*$C25 -> 350 | H25: =G25-F25 -> 200.50782 | I25: =SUM(G24:G25) -> 1070 | J25: =((I25-I23)/I23) -> 0.3375 | K25: =(I25-(SUM(F24:F25)))/I25 -> 0.62127553 | L25: =I25-(SUM(F24:F25)) -> 664.76482 | M25: =((L25-L23)/L23) -> 0.28339711
A26: {=XLOOKUP($B26,'Maestro de productos 2024'!$A$3:$A$163,'Maestro de productos 2024'!$B$3:$B$163,0)} -> ID-3828 | B26: Muffins de yogurt | C26: {=XLOOKUP(B26,'Maestro de productos 2024'!$B$189:$B$196,'Maestro de productos 2024'!$D$189:$D$196,"No encontrado",0)} -> 20 | D26: {=XLOOKUP(B26,'Maestro de productos 2024'!$B$189:$B$196,'Maestro de productos 2024'!$E$189:$E$196,"No encontrado",0)} -> 7.3010641 | E26: =C26-D26 -> 12.698936 | F26: =('Base de datos transacciones'!$H26)*$D26 -> 175.22554 | G26: ='Base de datos transacciones'!$H26*$C26 -> 480 | H26: =G26-F26 -> 304.77446
A27: {=XLOOKUP($B27,'Maestro de productos 2024'!$A$3:$A$163,'Maestro de productos 2024'!$B$3:$B$163,0)} -> ID-3826 | B27: Brownie triple chocolate | C27: {=XLOOKUP(B27,'Maestro de productos 2024'!$B$189:$B$196,'Maestro de productos 2024'!$D$189:$D$196,"No encontrado",0)} -> 20 | D27: {=XLOOKUP(B27,'Maestro de productos 2024'!$B$189:$B$196,'Maestro de productos 2024'!$E$189:$E$196,"No encontrado",0)} -> 7.1039722 | E27: =C27-D27 -> 12.896028 | F27: =('Base de datos transacciones'!$H27)*$D27 -> 106.55958 | G27: ='Base de datos transacciones'!$H27*$C27 -> 300 | H27: =G27-F27 -> 193.44042 | I27: =SUM(G26:G27) -> 780 | J27: =((I27-I25)/I25) -> -0.27102804 | K27: =(I27-(SUM(F26:F27)))/I27 -> 0.63873702 | L27: =I27-(SUM(F26:F27)) -> 498.21488 | M27: =((L27-L25)/L25) -> -0.25053965 | N27: =SUM(G20:G27) -> 3248 | O27: =((N27-N19)/N19) -> -0.020211161 | P27: =(N27-SUM(F20:F27))/N27 -> 0.63481631 | Q27: =N27-(SUM(F20:F27)) -> 2061.8834 | R27: =((Q27-Q19)/Q19) -> -0.029816991
A28: {=XLOOKUP($B28,'Maestro de productos 2024'!$A$3:$A$163,'Maestro de productos 2024'!$B$3:$B$163,0)} -> ID-3827 | B28: Galletas danesas | C28: {=XLOOKUP(B28,'Maestro de productos 2024'!$B$189:$B$196,'Maestro de productos 2024'!$D$189:$D$196,"No encontrado",0)} -> 7 | D28: {=XLOOKUP(B28,'Maestro de productos 2024'!$B$189:$B$196,'Maestro de productos 2024'!$E$189:$E$196,"No encontrado",0)} -> 2.6234601 | E28: =C28-D28 -> 4.3765399 | F28: =('Base de datos transacciones'!$H28)*$D28 -> 76.080342 | G28: ='Base de datos transacciones'!$H28*$C28 -> 203 | H28: =G28-F28 -> 126.91966
A29: {=XLOOKUP($B29,'Maestro de productos 2024'!$A$3:$A$163,'Maestro de productos 2024'!$B$3:$B$163,0)} -> ID-3825 | B29: Mini cheesecake | C29: {=XLOOKUP(B29,'Maestro de productos 2024'!$B$189:$B$196,'Maestro de productos 2024'!$D$189:$D$196,"No encontrado",0)} -> 20 | D29: {=XLOOKUP(B29,'Maestro de productos 2024'!$B$189:$B$196,'Maestro de productos 2024'!$E$189:$E$196,"No encontrado",0)} -> 7.6091462 | E29: =C29-D29 -> 12.390854 | F29: =('Base de datos transacciones'!$H29)*$D29 -> 121.74634 | G29: ='Base de datos transacciones'!$H29*$C29 -> 320 | H29: =G29-F29 -> 198.25366 | I29: =SUM(G28:G29) -> 523 | J29: =((I29-I27)/I27) -> -0.32948718 | K29: =(I29-(SUM(F28:F29)))/I29 -> 0.62174631 | L29: =I29-(SUM(F28:F29)) -> 325.17332 | M29: =((L29-L27)/L27) -> -0.34732315
A30: {=XLOOKUP($B30,'Maestro de productos 2024'!$A$3:$A$163,'Maestro de productos 2024'!$B$3:$B$163,0)} -> ID-3824 | B30: Galletas chocochips | C30: {=XLOOKUP(B30,'Maestro de productos 2024'!$B$189:$B$196,'Maestro de productos 2024'!$D$189:$D$196,"No encontrado",0)} -> 10 | D30: {=XLOOKUP(B30,'Maestro de productos 2024'!$B$189:$B$196,'Maestro de productos 2024'!$E$189:$E$196,"No encontrado",0)} -> 3.3375513 | E30: =C30-D30 -> 6.6624487 | F30: =('Base de datos transacciones'!$H30)*$D30 -> 106.80164 | G30: ='Base de datos transacciones'!$H30*$C30 -> 320 | H30: =G30-F30 -> 213.19836
A31: {=XLOOKUP($B31,'Maestro de productos 2024'!$A$3:$A$163,'Maestro de productos 2024'!$B$3:$B$163,0)} -> ID-3829 | B31: Besos de nuez | C31: {=XLOOKUP(B31,'Maestro de productos 2024'!$B$189:$B$196,'Maestro de productos 2024'!$D$189:$D$196,"No encontrado",0)} -> 7 | D31: {=XLOOKUP(B31,'Maestro de productos 2024'!$B$189:$B$196,'Maestro de productos 2024'!$E$189:$E$196,"No encontrado",0)} -> 2.9898436 | E31: =C31-D31 -> 4.0101564 | F31: =('Base de datos transacciones'!$H31)*$D31 -> 134.54296 | G31: ='Base de datos transacciones'!$H31*$C31 -> 315 | H31: =G31-F31 -> 180.45704 | I31: =SUM(G30:G31) -> 635 | J31: =((I31-I29)/I29) -> 0.21414914 | K31: =(I31-(SUM(F30:F31)))/I31 -> 0.61992976 | L31: =I31-(SUM(F30:F31)) -> 393.6554 | M31: =((L31-L29)/L29) -> 0.21060178
A32: {=XLOOKUP($B32,'Maestro de productos 2024'!$A$3:$A$163,'Maestro de productos 2024'!$B$3:$B$163,0)} -> ID-3828 | B32: Muffins de yogurt | C32: {=XLOOKUP(B32,'Maestro de productos 2024'!$B$189:$B$196,'Maestro de productos 2024'!$D$189:$D$196,"No encontrado",0)} -> 20 | D32: {=XLOOKUP(B32,'Maestro de productos 2024'!$B$189:$B$196,'Maestro de productos 2024'!$E$189:$E$196,"No encontrado",0)} -> 7.3010641 | E32: =C32-D32 -> 12.698936 | F32: =('Base de datos transacciones'!$H32)*$D32 -> 175.22554 | G32: ='Base de datos transacciones'!$H32*$C32 -> 480 | H32: =G32-F32 -> 304.77446
A33: {=XLOOKUP($B33,'Maestro de productos 2024'!$A$3:$A$163,'Maestro de productos 2024'!$B$3:$B$163,0)} -> ID-3826 | B33: Brownie triple chocolate | C33: {=XLOOKUP(B33,'Maestro de productos 2024'!$B$189:$B$196,'Maestro de productos 2024'!$D$189:$D$196,"No encontrado",0)} -> 20 | D33: {=XLOOKUP(B33,'Maestro de productos 2024'!$B$189:$B$196,'Maestro de productos 2024'!$E$189:$E$196,"No encontrado",0)} -> 7.1039722 | E33: =C33-D33 -> 12.896028 | F33: =('Base de datos transacciones'!$H33)*$D33 -> 113.66356 | G33: ='Base de datos transacciones'!$H33*$C33 -> 320 | H33: =G33-F33 -> 206.33644 | I33: =SUM(G32:G33) -> 800 | J33: =((I33-I31)/I31) -> 0.25984252 | K33: =(I33-(SUM(F32:F33)))/I33 -> 0.63888863 | L33: =I33-(SUM(F32:F33)) -> 511.11091 | M33: =((L33-L31)/L31) -> 0.29837139
A34: {=XLOOKUP($B34,'Maestro de productos 2024'!$A$3:$A$163,'Maestro de productos 2024'!$B$3:$B$163,0)} -> ID-3830 | B34: Flan de queso crema | C34: {=XLOOKUP(B34,'Maestro de productos 2024'!$B$189:$B$196,'Maestro de productos 2024'!$D$189:$D$196,"No encontrado",0)} -> 25 | D34: {=XLOOKUP(B34,'Maestro de productos 2024'!$B$189:$B$196,'Maestro de productos 2024'!$E$189:$E$196,"No encontrado",0)} -> 10.936667 | E34: =C34-D34 -> 14.063333 | F34: =('Base de datos transacciones'!$H34)*$D34 -> 196.86 | G34: ='Base de datos transacciones'!$H34*$C34 -> 450 | H34: =G34-F34 -> 253.14
A35: {=XLOOKUP($B35,'Maestro de productos 2024'!$A$3:$A$163,'Maestro de productos 2024'!$B$3:$B$163,0)} -> ID-3827 | B35: Galletas danesas | C35: {=XLOOKUP(B35,'Maestro de productos 2024'!$B$189:$B$196,'Maestro de productos 2024'!$D$189:$D$196,"No encontrado",0)} -> 7 | D35: {=XLOOKUP(B35,'Maestro de productos 2024'!$B$189:$B$196,'Maestro de productos 2024'!$E$189:$E$196,"No encontrado",0)} -> 2.6234601 | E35: =C35-D35 -> 4.3765399 | F35: =('Base de datos transacciones'!$H35)*$D35 -> 78.703802 | G35: ='Base de datos transacciones'!$H35*$C35 -> 210 | H35: =G35-F35 -> 131.2962 | I35: =SUM(G34:G35) -> 660 | J35: =((I35-I33)/I33) -> -0.175 | K35: =(I35-(SUM(F34:F35)))/I35 -> 0.58247909 | L35: =I35-(SUM(F34:F35)) -> 384.4362 | M35: =((L35-L33)/L33) -> -0.24784192
A36: {=XLOOKUP($B36,'Maestro de productos 2024'!$A$3:$A$163,'Maestro de productos 2024'!$B$3:$B$163,0)} -> ID-3825 | B36: Mini cheesecake | C36: {=XLOOKUP(B36,'Maestro de productos 2024'!$B$189:$B$196,'Maestro de productos 2024'!$D$189:$D$196,"No encontrado",0)} -> 20 | D36: {=XLOOKUP(B36,'Maestro de productos 2024'!$B$189:$B$196,'Maestro de productos 2024'!$E$189:$E$196,"No encontrado",0)} -> 7.6091462 | E36: =C36-D36 -> 12.390854 | F36: =('Base de datos transacciones'!$H36)*$D36 -> 121.74634 | G36: ='Base de datos transacciones'!$H36*$C36 -> 320 | H36: =G36-F36 -> 198.25366 | N36: =SUM(G28:G36) -> 2938 | O36: =((N36-N27)/N27) -> -0.09544335 | P36: =(N36-SUM(F28:F36))/N36 -> 0.61696034 | Q36: =N36-(SUM(F28:F36)) -> 1812.6295 | R36: =((Q36-Q27)/Q27) -> -0.12088652
A37: {=XLOOKUP($B37,'Maestro de productos 2024'!$A$3:$A$163,'Maestro de productos 2024'!$B$3:$B$163,0)} -> ID-3829 | B37: Besos de nuez | C37: {=XLOOKUP(B37,'Maestro de productos 2024'!$B$189:$B$196,'Maestro de productos 2024'!$D$189:$D$196,"No encontrado",0)} -> 7 | D37: {=XLOOKUP(B37,'Maestro de productos 2024'!$B$189:$B$196,'Maestro de productos 2024'!$E$189:$E$196,"No encontrado",0)} -> 2.9898436 | E37: =C37-D37 -> 4.0101564 | F37: =('Base de datos transacciones'!$H37)*$D37 -> 149.49218 | G37: ='Base de datos transacciones'!$H37*$C37 -> 350 | H37: =G37-F37 -> 200.50782 | I37: =SUM(G36:G37) -> 670 | J37: =((I37-I35)/I35) -> 0.015151515 | K37: =(I37-(SUM(F36:F37)))/I37 -> 0.59516639 | L37: =I37-(SUM(F36:F37)) -> 398.76148 | M37: =((L37-L35)/L35) -> 0.037263096
A38: {=XLOOKUP($B38,'Maestro de productos 2024'!$A$3:$A$163,'Maestro de productos 2024'!$B$3:$B$163,0)} -> ID-3824 | B38: Galletas chocochips | C38: {=XLOOKUP(B38,'Maestro de productos 2024'!$B$189:$B$196,'Maestro de productos 2024'!$D$189:$D$196,"No encontrado",0)} -> 10 | D38: {=XLOOKUP(B38,'Maestro de productos 2024'!$B$189:$B$196,'Maestro de productos 2024'!$E$189:$E$196,"No encontrado",0)} -> 3.3375513 | E38: =C38-D38 -> 6.6624487 | F38: =('Base de datos transacciones'!$H38)*$D38 -> 106.80164 | G38: ='Base de datos transacciones'!$H38*$C38 -> 320 | H38: =G38-F38 -> 213.19836
A39: {=XLOOKUP($B39,'Maestro de productos 2024'!$A$3:$A$163,'Maestro de productos 2024'!$B$3:$B$163,0)} -> ID-3828 | B39: Muffins de yogurt | C39: {=XLOOKUP(B39,'Maestro de productos 2024'!$B$189:$B$196,'Maestro de productos 2024'!$D$189:$D$196,"No encontrado",0)} -> 20 | D39: {=XLOOKUP(B39,'Maestro de productos 2024'!$B$189:$B$196,'Maestro de productos 2024'!$E$189:$E$196,"No encontrado",0)} -> 7.3010641 | E39: =C39-D39 -> 12.698936 | F39: =('Base de datos transacciones'!$H39)*$D39 -> 175.22554 | G39: ='Base de datos transacciones'!$H39*$C39 -> 480 | H39: =G39-F39 -> 304.77446 | I39: =SUM(G38:G39) -> 800 | J39: =((I39-I37)/I37) -> 0.19402985 | K39: =(I39-(SUM(F38:F39)))/I39 -> 0.64746603 | L39: =I39-(SUM(F38:F39)) -> 517.97282 | M39: =((L39-L37)/L37) -> 0.298954
A40: {=XLOOKUP($B40,'Maestro de productos 2024'!$A$3:$A$163,'Maestro de productos 2024'!$B$3:$B$163,0)} -> ID-3826 | B40: Brownie triple chocolate | C40: {=XLOOKUP(B40,'Maestro de productos 2024'!$B$189:$B$196,'Maestro de productos 2024'!$D$189:$D$196,"No encontrado",0)} -> 20 | D40: {=XLOOKUP(B40,'Maestro de productos 2024'!$B$189:$B$196,'Maestro de productos 2024'!$E$189:$E$196,"No encontrado",0)} -> 7.1039722 | E40: =C40-D40 -> 12.896028 | F40: =('Base de datos transacciones'!$H40)*$D40 -> 127.8715 | G40: ='Base de datos transacciones'!$H40*$C40 -> 360 | H40: =G40-F40 -> 232.1285
...

Sheet Dashboard de rentabilidad
B1: Selector de año: | C1: 2025
A4: ID | B4: Producto | C4: IT | D4: CV | E4: UB | F4: MGB | G4: GO | H4: UO | I4: Impuestos (1%RESICO) | J4: UN | K4: CantidadVendida | L4: Desperdicio(tasa) | M4: MixVtasQ | N4: MixVtas$ | O4: SMV
A5: {=XLOOKUP($B5,'Maestro de productos 2024'!$A$3:$A$163,'Maestro de productos 2024'!$B$3:$B$163,0)} -> ID-3824 | B5: ='Maestro de productos 2024'!$A$3 -> Galletas chocochips | C5: =IF($C$1="Todos",SUMIF('Base de datos transacciones'!$A$2:$A$162,$A5,'Base de datos transacciones'!$K$2:$K$162),SUMIFS('Base de datos transacciones'!$K$2:$K$162,'Base de datos transacciones'!$C$2:$C$162,$C$1,'Base de datos transacciones'!$A$2:$A$162,$A5)) -> 5790 | D5: =IF($C$1="Todos",SUMIF('Base de datos transacciones'!$A$2:$A$162,$A5,'Base de datos transacciones'!$J$2:$J$162),SUMIFS('Base de datos transacciones'!$J$2:$J$162,'Base de datos transacciones'!$C$2:$C$162,$C$1,'Base de datos transacciones'!$A$2:$A$162,$A5)) -> 2357.5398 | E5: =C5-D5 -> 3432.4602 | F5: =E5/C5 -> 0.5928256 | G5: =IF($C$1="Todos",(($C5*0.2)+'Maestro de productos 2024'!$I189+'Maestro de productos 2025'!$I189),IF($C$1=2024,(($C5*0.2)+'Maestro de productos 2024'!$I189),(($C5*0.2)+'Maestro de productos 2025'!$I189))) -> 1276.0806 | H5: =E5-G5 -> 2156.3797 | I5: =C5*0.01 -> 57.9 | J5: =H5-I5 -> 2098.4797 | K5: =IF($C$1="Todos",SUMIF('Base de datos transacciones'!$A$2:$A$162,$A5,'Base de datos transacciones'!$H$2:$H$162),SUMIFS('Base de datos transacciones'!$H$2:$H$162,'Base de datos transacciones'!$C$2:$C$162,$C$1,'Base de datos transacciones'!$A$2:$A$162,$A5)) -> 579 | L5: =IF($C$1="Todos",(($D$5-('Maestro de productos 2024'!$J$189+'Maestro de productos 2025'!$J$189))/$D$5),IF($C$1=2024,(($D$5-'Maestro de productos 2024'!$J$189)/$D$5),(($D$5-'Maestro de productos 2025'!$J$189)/$D$5))) -> -1.4559501 | M5: =K5/$K$13 -> 0.30361825 | N5: =C5/$C$13 -> 0.21307132 | O5: =IF($C$1="Todos",('Maestro de productos 2025'!$G$197*('Maestro de productos 2025'!L189-'Maestro de productos 2024'!L189)*'Maestro de productos 2024'!K189),IF($C$1=2024,($K$13*(M5-0.125)*'Maestro de productos 2024'!K189),($K$13*(M5-0.125)*'Maestro de productos 2025'!K189))) -> 2019.3122
A6: {=XLOOKUP($B6,'Maestro de productos 2024'!$A$3:$A$163,'Maestro de productos 2024'!$B$3:$B$163,0)} -> ID-3825 | B6: ='Maestro de productos 2024'!$A$26 -> Mini cheesecake | C6: =IF($C$1="Todos",SUMIF('Base de datos transacciones'!$A$2:$A$162,$A6,'Base de datos transacciones'!$K$2:$K$162),SUMIFS('Base de datos transacciones'!$K$2:$K$162,'Base de datos transacciones'!$C$2:$C$162,$C$1,'Base de datos transacciones'!$A$2:$A$162,$A6)) -> 3475 | D6: =IF($C$1="Todos",SUMIF('Base de datos transacciones'!$A$2:$A$162,$A6,'Base de datos transacciones'!$J$2:$J$162),SUMIFS('Base de datos transacciones'!$J$2:$J$162,'Base de datos transacciones'!$C$2:$C$162,$C$1,'Base de datos transacciones'!$A$2:$A$162,$A6)) -> 1426.7664 | E6: =C6-D6 -> 2048.2336 | F6: =E6/C6 -> 0.58941974 | G6: =IF($C$1="Todos",(($C6*0.2)+'Maestro de productos 2024'!$I190+'Maestro de productos 2025'!$I190),IF($C$1=2024,(($C6*0.2)+'Maestro de productos 2024'!$I190),(($C6*0.2)+'Maestro de productos 2025'!$I190))) -> 746.32253 | H6: =E6-G6 -> 1301.9111 | I6: =C6*0.01 -> 34.75 | J6: =H6-I6 -> 1267.1611 | K6: =IF($C$1="Todos",SUMIF('Base de datos transacciones'!$A$2:$A$162,$A6,'Base de datos transacciones'!$H$2:$H$162),SUMIFS('Base de datos transacciones'!$H$2:$H$162,'Base de datos transacciones'!$C$2:$C$162,$C$1,'Base de datos transacciones'!$A$2:$A$162,$A6)) -> 139 | L6: =IF($C$1="Todos",(($D$6-('Maestro de productos 2024'!$J$190+'Maestro de productos 2025'!$J$190))/$D$6),IF($C$1=2024,(($D$6-'Maestro de productos 2024'!$J$190)/$D$6),(($D$6-'Maestro de productos 2025'!$J$190)/$D$6))) -> -1.4355774 | M6: =K6/$K$13 -> 0.072889355 | N6: =C6/$C$13 -> 0.12787959 | O6: =IF($C$1="Todos",('Maestro de productos 2025'!$G$197*('Maestro de productos 2025'!L190-'Maestro de productos 2024'!L190)*'Maestro de productos 2024'!K190),IF($C$1=2024,($K$13*(M6-0.125)*'Maestro de productos 2024'!K190),($K$13*(M6-0.125)*'Maestro de productos 2025'!K190))) -> -1464.3397
A7: {=XLOOKUP($B7,'Maestro de productos 2024'!$A$3:$A$163,'Maestro de productos 2024'!$B$3:$B$163,0)} -> ID-3826 | B7: ='Maestro de productos 2024'!$A$51 -> Brownie triple chocolate | C7: =IF($C$1="Todos",SUMIF('Base de datos transacciones'!$A$2:$A$162,$A7,'Base de datos transacciones'!$K$2:$K$162),SUMIFS('Base de datos transacciones'!$K$2:$K$162,'Base de datos transacciones'!$C$2:$C$162,$C$1,'Base de datos transacciones'!$A$2:$A$162,$A7)) -> 3220 | D7: =IF($C$1="Todos",SUMIF('Base de datos transacciones'!$A$2:$A$162,$A7,'Base de datos transacciones'!$J$2:$J$162),SUMIFS('Base de datos transacciones'!$J$2:$J$162,'Base de datos transacciones'!$C$2:$C$162,$C$1,'Base de datos transacciones'!$A$2:$A$162,$A7)) -> 1299.7729 | E7: =C7-D7 -> 1920.2271 | F7: =E7/C7 -> 0.59634383 | G7: =IF($C$1="Todos",(($C7*0.2)+'Maestro de productos 2024'!$I191+'Maestro de productos 2025'!$I191),IF($C$1=2024,(($C7*0.2)+'Maestro de productos 2024'!$I191),(($C7*0.2)+'Maestro de productos 2025'!$I191))) -> 652.07312 | H7: =E7-G7 -> 1268.154 | I7: =C7*0.01 -> 32.2 | J7: =H7-I7 -> 1235.954 | K7: =IF($C$1="Todos",SUMIF('Base de datos transacciones'!$A$2:$A$162,$A7,'Base de datos transacciones'!$H$2:$H$162),SUMIFS('Base de datos transacciones'!$H$2:$H$162,'Base de datos transacciones'!$C$2:$C$162,$C$1,'Base de datos transacciones'!$A$2:$A$162,$A7)) -> 161 | L7: =IF($C$1="Todos",(($D$7-('Maestro de productos 2024'!$J$191+'Maestro de productos 2025'!$J$191))/$D$7),IF($C$1=2024,(($D$7-'Maestro de productos 2024'!$J$191)/$D$7),(($D$7-'Maestro de productos 2025'!$J$191)/$D$7))) -> -1.4773559 | M7: =K7/$K$13 -> 0.0844258 | N7: =C7/$C$13 -> 0.11849562 | O7: =IF($C$1="Todos",('Maestro de productos 2025'!$G$197*('Maestro de productos 2025'!L191-'Maestro de productos 2024'!L191)*'Maestro de productos 2024'!K191),IF($C$1=2024,($K$13*(M7-0.125)*'Maestro de productos 2024'!K191),($K$13*(M7-0.125)*'Maestro de productos 2025'!K191))) -> -922.84207
A8: {=XLOOKUP($B8,'Maestro de productos 2024'!$A$3:$A$163,'Maestro de productos 2024'!$B$3:$B$163,0)} -> ID-3827 | B8: ='Maestro de productos 2024'!$A$75 -> Galletas danesas | C8: =IF($C$1="Todos",SUMIF('Base de datos transacciones'!$A$2:$A$162,$A8,'Base de datos transacciones'!$K$2:$K$162),SUMIFS('Base de datos transacciones'!$K$2:$K$162,'Base de datos transacciones'!$C$2:$C$162,$C$1,'Base de datos transacciones'!$A$2:$A$162,$A8)) -> 2975 | D8: =IF($C$1="Todos",SUMIF('Base de datos transacciones'!$A$2:$A$162,$A8,'Base de datos transacciones'!$J$2:$J$162),SUMIFS('Base de datos transacciones'!$J$2:$J$162,'Base de datos transacciones'!$C$2:$C$162,$C$1,'Base de datos transacciones'!$A$2:$A$162,$A8)) -> 1322.5063 | E8: =C8-D8 -> 1652.4937 | F8: =E8/C8 -> 0.55546007 | G8: =IF($C$1="Todos",(($C8*0.2)+'Maestro de productos 2024'!$I192+'Maestro de productos 2025'!$I192),IF($C$1=2024,(($C8*0.2)+'Maestro de productos 2024'!$I192),(($C8*0.2)+'Maestro de productos 2025'!$I192))) -> 688.35339 | H8: =E8-G8 -> 964.14033 | I8: =C8*0.01 -> 29.75 | J8: =H8-I8 -> 934.39033 | K8: =IF($C$1="Todos",SUMIF('Base de datos transacciones'!$A$2:$A$162,$A8,'Base de datos transacciones'!$H$2:$H$162),SUMIFS('Base de datos transacciones'!$H$2:$H$162,'Base de datos transacciones'!$C$2:$C$162,$C$1,'Base de datos transacciones'!$A$2:$A$162,$A8)) -> 425 | L8: =IF($C$1="Todos",(($D$8-('Maestro de productos 2024'!$J$192+'Maestro de productos 2025'!$J$192))/$D$8),IF($C$1=2024,(($D$8-'Maestro de productos 2024'!$J$192)/$D$8),(($D$8-'Maestro de productos 2025'!$J$192)/$D$8))) -> -1.2495167 | M8: =K8/$K$13 -> 0.22286314 | N8: =C8/$C$13 -> 0.10947965 | O8: =IF($C$1="Todos",('Maestro de productos 2025'!$G$197*('Maestro de productos 2025'!L192-'Maestro de productos 2024'!L192)*'Maestro de productos 2024'!K192),IF($C$1=2024,($K$13*(M8-0.125)*'Maestro de productos 2024'!K192),($K$13*(M8-0.125)*'Maestro de productos 2025'!K192))) -> 725.63915
A9: {=XLOOKUP($B9,'Maestro de productos 2024'!$A$3:$A$163,'Maestro de productos 2024'!$B$3:$B$163,0)} -> ID-3828 | B9: ='Maestro de productos 2024'!$A$96 -> Muffins de yogurt | C9: =IF($C$1="Todos",SUMIF('Base de datos transacciones'!$A$2:$A$162,$A9,'Base de datos transacciones'!$K$2:$K$162),SUMIFS('Base de datos transacciones'!$K$2:$K$162,'Base de datos transacciones'!$C$2:$C$162,$C$1,'Base de datos transacciones'!$A$2:$A$162,$A9)) -> 7812 | D9: =IF($C$1="Todos",SUMIF('Base de datos transacciones'!$A$2:$A$162,$A9,'Base de datos transacciones'!$J$2:$J$162),SUMIFS('Base de datos transacciones'!$J$2:$J$162,'Base de datos transacciones'!$C$2:$C$162,$C$1,'Base de datos transacciones'!$A$2:$A$162,$A9)) -> 3109.6786 | E9: =C9-D9 -> 4702.3214 | F9: =E9/C9 -> 0.60193566 | G9: =IF($C$1="Todos",(($C9*0.2)+'Maestro de productos 2024'!$I193+'Maestro de productos 2025'!$I193),IF($C$1=2024,(($C9*0.2)+'Maestro de productos 2024'!$I193),(($C9*0.2)+'Maestro de productos 2025'!$I193))) -> 1562.4 | H9: =E9-G9 -> 3139.9214 | I9: =C9*0.01 -> 78.12 | J9: =H9-I9 -> 3061.8014 | K9: =IF($C$1="Todos",SUMIF('Base de datos transacciones'!$A$2:$A$162,$A9,'Base de datos transacciones'!$H$2:$H$162),SUMIFS('Base de datos transacciones'!$H$2:$H$162,'Base de datos transacciones'!$C$2:$C$162,$C$1,'Base de datos transacciones'!$A$2:$A$162,$A9)) -> 372 | L9: =IF($C$1="Todos",(($D$9-('Maestro de productos 2024'!$J$193+'Maestro de productos 2025'!$J$193))/$D$9),IF($C$1=2024,(($D$9-'Maestro de productos 2024'!$J$193)/$D$9),(($D$9-'Maestro de productos 2025'!$J$193)/$D$9))) -> -1.5121567 | M9: =K9/$K$13 -> 0.19507079 | N9: =C9/$C$13 -> 0.28748068 | O9: =IF($C$1="Todos",('Maestro de productos 2025'!$G$197*('Maestro de productos 2025'!L193-'Maestro de productos 2024'!L193)*'Maestro de productos 2024'!K193),IF($C$1=2024,($K$13*(M9-0.125)*'Maestro de productos 2024'!K193),($K$13*(M9-0.125)*'Maestro de productos 2025'!K193))) -> 1689.1067
A10: {=XLOOKUP($B10,'Maestro de productos 2024'!$A$3:$A$163,'Maestro de productos 2024'!$B$3:$B$163,0)} -> ID-3829 | B10: ='Maestro de productos 2024'!$A$119 -> Besos de nuez | C10: =IF($C$1="Todos",SUMIF('Base de datos transacciones'!$A$2:$A$162,$A10,'Base de datos transacciones'!$K$2:$K$162),SUMIFS('Base de datos transacciones'!$K$2:$K$162,'Base de datos transacciones'!$C$2:$C$162,$C$1,'Base de datos transacciones'!$A$2:$A$162,$A10)) -> 720 | D10: =IF($C$1="Todos",SUMIF('Base de datos transacciones'!$A$2:$A$162,$A10,'Base de datos transacciones'!$J$2:$J$162),SUMIFS('Base de datos transacciones'!$J$2:$J$162,'Base de datos transacciones'!$C$2:$C$162,$C$1,'Base de datos transacciones'!$A$2:$A$162,$A10)) -> 288.86949 | E10: =C10-D10 -> 431.13051 | F10: =E10/C10 -> 0.59879238 | G10: =IF($C$1="Todos",(($C10*0.2)+'Maestro de productos 2024'!$I194+'Maestro de productos 2025'!$I194),IF($C$1=2024,(($C10*0.2)+'Maestro de productos 2024'!$I194),(($C10*0.2)+'Maestro de productos 2025'!$I194))) -> 216.21737 | H10: =E10-G10 -> 214.91314 | I10: =C10*0.01 -> 7.2 | J10: =H10-I10 -> 207.71314 | K10: =IF($C$1="Todos",SUMIF('Base de datos transacciones'!$A$2:$A$162,$A10,'Base de datos transacciones'!$H$2:$H$162),SUMIFS('Base de datos transacciones'!$H$2:$H$162,'Base de datos transacciones'!$C$2:$C$162,$C$1,'Base de datos transacciones'!$A$2:$A$162,$A10)) -> 80 | L10: =IF($C$1="Todos",(($D$10-('Maestro de productos 2024'!$J$194+'Maestro de productos 2025'!$J$194))/$D$10),IF($C$1=2024,(($D$10-'Maestro de productos 2024'!$J$194)/$D$10),(($D$10-'Maestro de productos 2025'!$J$194)/$D$10))) -> -1.4924751 | M10: =K10/$K$13 -> 0.041950708 | N10: =C10/$C$13 -> 0.026495915 | O10: =IF($C$1="Todos",('Maestro de productos 2025'!$G$197*('Maestro de productos 2025'!L194-'Maestro de productos 2024'!L194)*'Maestro de productos 2024'!K194),IF($C$1=2024,($K$13*(M10-0.125)*'Maestro de productos 2024'!K194),($K$13*(M10-0.125)*'Maestro de productos 2025'!K194))) -> -853.50369
A11: {=XLOOKUP($B11,'Maestro de productos 2024'!$A$3:$A$163,'Maestro de productos 2024'!$B$3:$B$163,0)} -> ID-3830 | B11: ='Maestro de productos 2024'!$A$140 -> Flan de queso crema | C11: =IF($C$1="Todos",SUMIF('Base de datos transacciones'!$A$2:$A$162,$A11,'Base de datos transacciones'!$K$2:$K$162),SUMIFS('Base de datos transacciones'!$K$2:$K$162,'Base de datos transacciones'!$C$2:$C$162,$C$1,'Base de datos transacciones'!$A$2:$A$162,$A11)) -> 522 | D11: =IF($C$1="Todos",SUMIF('Base de datos transacciones'!$A$2:$A$162,$A11,'Base de datos transacciones'!$J$2:$J$162),SUMIFS('Base de datos transacciones'!$J$2:$J$162,'Base de datos transacciones'!$C$2:$C$162,$C$1,'Base de datos transacciones'!$A$2:$A$162,$A11)) -> 214.86375 | E11: =C11-D11 -> 307.13625 | F11: =E11/C11 -> 0.58838362 | G11: =IF($C$1="Todos",(($C11*0.2)+'Maestro de productos 2024'!$I195+'Maestro de productos 2025'!$I195),IF($C$1=2024,(($C11*0.2)+'Maestro de productos 2024'!$I195),(($C11*0.2)+'Maestro de productos 2025'!$I195))) -> 104.4 | H11: =E11-G11 -> 202.73625 | I11: =C11*0.01 -> 5.22 | J11: =H11-I11 -> 197.51625 | K11: =IF($C$1="Todos",SUMIF('Base de datos transacciones'!$A$2:$A$162,$A11,'Base de datos transacciones'!$H$2:$H$162),SUMIFS('Base de datos transacciones'!$H$2:$H$162,'Base de datos transacciones'!$C$2:$C$162,$C$1,'Base de datos transacciones'!$A$2:$A$162,$A11)) -> 18 | L11: =IF($C$1="Todos",(($D$11-('Maestro de productos 2024'!$J$195+'Maestro de productos 2025'!$J$195))/$D$11),IF($C$1=2024,(($D$11-'Maestro de productos 2024'!$J$195)/$D$11),(($D$11-'Maestro de productos 2025'!$J$195)/$D$11))) -> -1.4294466 | M11: =K11/$K$13 -> 0.0094389093 | N11: =C11/$C$13 -> 0.019209539 | O11: =IF($C$1="Todos",('Maestro de productos 2025'!$G$197*('Maestro de productos 2025'!L195-'Maestro de productos 2024'!L195)*'Maestro de productos 2024'!K195),IF($C$1=2024,($K$13*(M11-0.125)*'Maestro de productos 2024'!K195),($K$13*(M11-0.125)*'Maestro de productos 2025'!K195))) -> -3760.2862
A12: {=XLOOKUP($B12,'Maestro de productos 2024'!$A$3:$A$163,'Maestro de productos 2024'!$B$3:$B$163,0)} -> ID-3831 | B12: ='Maestro de productos 2024'!$A$163 -> Muffin de chocolate | C12: =IF($C$1="Todos",SUMIF('Base de datos transacciones'!$A$2:$A$162,$A12,'Base de datos transacciones'!$K$2:$K$162),SUMIFS('Base de datos transacciones'!$K$2:$K$162,'Base de datos transacciones'!$C$2:$C$162,$C$1,'Base de datos transacciones'!$A$2:$A$162,$A12)) -> 2660 | D12: =IF($C$1="Todos",SUMIF('Base de datos transacciones'!$A$2:$A$162,$A12,'Base de datos transacciones'!$J$2:$J$162),SUMIFS('Base de datos transacciones'!$J$2:$J$162,'Base de datos transacciones'!$C$2:$C$162,$C$1,'Base de datos transacciones'!$A$2:$A$162,$A12)) -> 1049.3381 | E12: =C12-D12 -> 1610.6619 | F12: =E12/C12 -> 0.605512 | G12: =IF($C$1="Todos",(($C12*0.2)+'Maestro de productos 2024'!$I196+'Maestro de productos 2025'!$I196),IF($C$1=2024,(($C12*0.2)+'Maestro de productos 2024'!$I196),(($C12*0.2)+'Maestro de productos 2025'!$I196))) -> 587.22832 | H12: =E12-G12 -> 1023.4336 | I12: =C12*0.01 -> 26.6 | J12: =H12-I12 -> 996.83359 | K12: =IF($C$1="Todos",SUMIF('Base de datos transacciones'!$A$2:$A$162,$A12,'Base de datos transacciones'!$H$2:$H$162),SUMIFS('Base de datos transacciones'!$H$2:$H$162,'Base de datos transacciones'!$C$2:$C$162,$C$1,'Base de datos transacciones'!$A$2:$A$162,$A12)) -> 133 | L12: =IF($C$1="Todos",(($D$12-('Maestro de productos 2024'!$J$196+'Maestro de productos 2025'!$J$196))/$D$12),IF($C$1=2024,(($D$12-'Maestro de productos 2024'!$J$196)/$D$12),(($D$12-'Maestro de productos 2025'!$J$196)/$D$12))) -> -1.5349313 | M12: =K12/$K$13 -> 0.069743052 | N12: =C12/$C$13 -> 0.097887687 | O12: =IF($C$1="Todos",('Maestro de productos 2025'!$G$197*('Maestro de productos 2025'!L196-'Maestro de productos 2024'!L196)*'Maestro de productos 2024'!K196),IF($C$1=2024,($K$13*(M12-0.125)*'Maestro de productos 2024'!K196),($K$13*(M12-0.125)*'Maestro de productos 2025'!K196))) -> -1276.1165
B13: Total | C13: =SUM(C5:C12) -> 27174 | D13: =SUM(D5:D12) -> 11069.335 | E13: =SUM(E5:E12) -> 16104.665 | F13: =E13/C13 -> 0.59264977 | G13: =SUM(G5:G12) -> 5833.0753 | H13: =SUM(H5:H12) -> 10271.589 | I13: =SUM(I5:I12) -> 271.74 | J13: =SUM(J5:J12) -> 9999.8494 | K13: =SUM(K5:K12) -> 1907
C30: IT | D30: CV | E30: MGB
B31: Promedio 2025 | C31: 3396.75 | D31: 1383.6669 | E31: =(C31-D31)/C31 -> 0.59264977
C33: =C31*1.1 -> 3736.425 | E33: =(C33-D31)/C33 -> 0.6296816
B35: Promedio 2024 | C35: 3448.875 | D35: 1277.6493 | E35: =(C31-D35)/C31 -> 0.62386124
A38: ID | B38: 2024 | C38: UB | D38: % Individual | E38: % Acumulado
A39: ID-3828 | B39: Muffins de yogurt | C39: 3962.068 | D39: =C39/$C$47 -> 0.22810089 | E39: =D39 -> 0.22810089
A40: ID-3824 | B40: Galletas chocochips | C40: 3764.2835 | D40: =C40/$C$47 -> 0.2167142 | E40: =E39+D40 -> 0.44481509
A41: ID-3826 | B41: Brownie Triple Chocolate | C41: 3185.3189 | D41: =C41/$C$47 -> 0.18338253 | E41: =E40+D41 -> 0.62819762
A42: ID-3825 | B42: Mini cheesecake | C42: 1920.5823 | D42: =C42/$C$47 -> 0.11057017 | E42: =E41+D42 -> 0.73876779
A43: ID-3829 | B43: Besos de nuez | C43: 1539.9001 | D43: =C43/$C$47 -> 0.088653847 | E43: =E42+D43 -> 0.82742164
A44: ID-3827 | B44: Galletas danesas | C44: 1286.7027 | D44: =C44/$C$47 -> 0.074076981 | E44: =E43+D44 -> 0.90149862
A45: ID-3830 | B45: Flan de queso crema | C45: 1167.2567 | D45: =C45/$C$47 -> 0.067200331 | E45: =E44+D45 -> 0.96869895
A46: ID-3831 | B46: Muffin de chocolate | C46: 543.69308 | D46: =C46/$C$47 -> 0.031301046 | E46: =E45+D46 -> 1
C47: =SUM(C39:C46) -> 17369.805
B48: 2025 | C48: UB | D48: % Individual | E48: % Acumulado
A49: ID-3828 | B49: Muffins de yogurt | C49: 4702.3214 | D49: =C49/$C$57 -> 0.29198505 | E49: =D49 -> 0.29198505 | M49: CV 2024 | N49: PV 2025 | O49: CantidadVendida2025 | P49: IT | Q49: TotalCOGS
A50: ID-3824 | B50: Galletas chocochips | C50: 3432.4602 | D50: =C50/$C$57 -> 0.21313454 | E50: =E49+D50 -> 0.50511959 | M50: 3.3375513 | N50: 10 | O50: 579 | P50: =N50*O50 -> 5790 | Q50: =M50*O50 -> 1932.4422
A51: ID-3826 | B51: Brownie Triple Chocolate | C51: 1920.2271 | D51: =C51/$C$57 -> 0.11923422 | E51: =E50+D51 -> 0.62435381 | M51: 7.6091462 | N51: 25 | O51: 139 | P51: =N51*O51 -> 3475 | Q51: =M51*O51 -> 1057.6713
A52: ID-3825 | B52: Mini cheesecake | C52: 2048.2336 | D52: =C52/$C$57 -> 0.12718263 | E52: =E51+D52 -> 0.75153644 | M52: 7.1039722 | N52: 20 | O52: 161 | P52: =N52*O52 -> 3220 | Q52: =M52*O52 -> 1143.7395
A53: ID-3827 | B53: Galletas danesas | C53: 1652.4937 | D53: =C53/$C$57 -> 0.10260963 | E53: =E52+D53 -> 0.85414607 | M53: 2.6234601 | N53: 7 | O53: 425 | P53: =N53*O53 -> 2975 | Q53: =M53*O53 -> 1114.9705
A54: ID-3831 | B54: Muffin de chocolate | C54: 1610.6619 | D54: =C54/$C$57 -> 0.10001214 | E54: =E53+D54 -> 0.9541582 | M54: 7.3010641 | N54: 21 | O54: 372 | P54: =N54*O54 -> 7812 | Q54: =M54*O54 -> 2715.9958
A55: ID-3829 | B55: Besos de nuez | C55: 431.13051 | D55: =C55/$C$57 -> 0.026770536 | E55: =E54+D55 -> 0.98092874 | M55: 2.9898436 | N55: 9 | O55: 80 | P55: =N55*O55 -> 720 | Q55: =M55*O55 -> 239.18749
A56: ID-3830 | B56: Flan de queso crema | C56: 307.13625 | D56: =C56/$C$57 -> 0.01907126 | E56: =E55+D56 -> 1 | M56: 10.936667 | N56: 29 | O56: 18 | P56: =N56*O56 -> 522 | Q56: =M56*O56 -> 196.86
C57: =SUM(C49:C56) -> 16104.665 | M57: 7.0549267 | N57: 20 | O57: 133 | P57: =N57*O57 -> 2660 | Q57: =M57*O57 -> 938.30526
B58: Todos | C58: UB | D58: % Individual | E58: % Acumulado | P58: =SUM(P50:P57) -> 27174 | Q58: =SUM(Q50:Q57) -> 9339.1722
A59: ID-3828 | B59: Muffins de yogurt | C59: 8664.3894 | D59: =C59/$C$67 -> 0.25883575 | E59: =D59 -> 0.25883575 | Q59: =(P58-Q58)/P58 -> 0.65631956
A60: ID-3824 | B60: Galletas chocochips | C60: 7196.7438 | D60: =C60/$C$67 -> 0.21499202 | E60: =D60+E59 -> 0.47382776
A61: ID-3826 | B61: Brownie Triple Chocolate | C61: 5105.546 | D61: =C61/$C$67 -> 0.15252059 | E61: =D61+E60 -> 0.62634835 | J61: 3.3375513 | K61: =J61*P61 -> 1885.7165 | L61: =Q61-K61 -> 3764.2835 | N61: 4.071744 | O61: 10 | P61: 565 | Q61: =O61*P61 -> 5650 | R61: =N61*P61 -> 2300.5354 | S61: =Q61-R61 -> 3349.4646
A62: ID-3825 | B62: Mini cheesecake | C62: 3968.8159 | D62: =C62/$C$67 -> 0.11856247 | E62: =D62+E61 -> 0.74491083 | J62: 7.6091462 | K62: =J62*P62 -> 1179.4177 | L62: =Q62-K62 -> 2695.5823 | N62: 10.264506 | O62: 25 | P62: 155 | Q62: =O62*P62 -> 3875 | R62: =N62*P62 -> 1590.9985 | S62: =Q62-R62 -> 2284.0015
...

Sheet Base de datos transacciones
A1: ID | B1: FechaDelPedido | C1: Año | D1: Mes | E1: Producto | F1: PV | G1: CV | H1: CantidadVendida | I1: CantidadNoVendida | J1: TotalCV | K1: IT | L1: Perdidas
A2: {=XLOOKUP($E2,'Maestro de productos 2024'!$A$3:$A$163,'Maestro de productos 2024'!$B$3:$B$163,0)} -> ID-3824 | B2: 45373 | C2: =YEAR(B2) -> 2024 | D2: =MONTH(B2) -> 3 | E2: Galletas chocochips | F2: {=XLOOKUP(E2,'Maestro de productos 2024'!$B$189:$B$196,'Maestro de productos 2024'!$D$189:$D$196,"No encontrado",0)} -> 10 | G2: {=XLOOKUP(E2,'Maestro de productos 2024'!$B$189:$B$196,'Maestro de productos 2024'!$E$189:$E$196,"No encontrado",0)} -> 3.3375513 | H2: 32 | I2: {=IF((XLOOKUP($E2,'Maestro de productos 2024'!$B$189:$B$196,'Maestro de productos 2024'!$C$189:$C$196,"No encontrado",0)-H2)<=0,"0",(VLOOKUP($E2,'Maestro de productos 2024'!$B$189:$C$196,2,0)-$H2))} -> 0 | J2: =($H2*$G2) -> 106.80164 | K2: =$F2*$H2 -> 320
